2023-06-19 16:34:43 ERROR 400 response executing GraphQL.
2023-06-19 16:34:43 ERROR {"errors":[{"message":"Invalid sweep config: invalid hyperparameter configuration: hidden_dim","path":["upsertSweep"]}],"data":{"upsertSweep":null}}
2023-06-19 16:34:43 ERROR Traceback (most recent call last):
  File "/home/didi/.local/lib/python3.8/site-packages/wandb/sdk/lib/retry.py", line 131, in __call__
    result = self._call_fn(*args, **kwargs)
  File "/home/didi/.local/lib/python3.8/site-packages/wandb/sdk/internal/internal_api.py", line 320, in execute
    return self.client.execute(*args, **kwargs)  # type: ignore
  File "/home/didi/.local/lib/python3.8/site-packages/wandb/vendor/gql-0.2.0/wandb_gql/client.py", line 52, in execute
    result = self._get_result(document, *args, **kwargs)
  File "/home/didi/.local/lib/python3.8/site-packages/wandb/vendor/gql-0.2.0/wandb_gql/client.py", line 60, in _get_result
    return self.transport.execute(document, *args, **kwargs)
  File "/home/didi/.local/lib/python3.8/site-packages/wandb/sdk/lib/gql_request.py", line 56, in execute
    request.raise_for_status()
  File "/home/didi/.local/lib/python3.8/site-packages/requests/models.py", line 953, in raise_for_status
    raise HTTPError(http_error_msg, response=self)
requests.exceptions.HTTPError: 400 Client Error: Bad Request for url: https://api.wandb.ai/graphql

During handling of the above exception, another exception occurred:

Traceback (most recent call last):
  File "/home/didi/.local/lib/python3.8/site-packages/wandb/cli/cli.py", line 106, in wrapper
    return func(*args, **kwargs)
  File "/home/didi/.local/lib/python3.8/site-packages/wandb/cli/cli.py", line 853, in sweep
    sweep_id, warnings = api.upsert_sweep(
  File "/home/didi/.local/lib/python3.8/site-packages/wandb/apis/internal.py", line 129, in upsert_sweep
    return self.api.upsert_sweep(*args, **kwargs)
  File "/home/didi/.local/lib/python3.8/site-packages/wandb/apis/normalize.py", line 73, in wrapper
    raise err
  File "/home/didi/.local/lib/python3.8/site-packages/wandb/apis/normalize.py", line 41, in wrapper
    return func(*args, **kwargs)
  File "/home/didi/.local/lib/python3.8/site-packages/wandb/sdk/internal/internal_api.py", line 2595, in upsert_sweep
    raise e
  File "/home/didi/.local/lib/python3.8/site-packages/wandb/sdk/internal/internal_api.py", line 2589, in upsert_sweep
    response = self.gql(
  File "/home/didi/.local/lib/python3.8/site-packages/wandb/sdk/internal/internal_api.py", line 292, in gql
    ret = self._retry_gql(
  File "/home/didi/.local/lib/python3.8/site-packages/wandb/sdk/lib/retry.py", line 147, in __call__
    retry_timedelta_triggered = check_retry_fn(e)
  File "/home/didi/.local/lib/python3.8/site-packages/wandb/util.py", line 821, in no_retry_4xx
    raise UsageError(body["errors"][0]["message"])
wandb.errors.UsageError: Invalid sweep config: invalid hyperparameter configuration: hidden_dim

